too few successful tests, not using stored timings
Running doctests with ID 2019-12-31-18-01-54-b441a7ec.
Git branch: develop
Using --optional=4ti2,benzene,bliss,buckygen,build,cbc,cryptominisat,csdp,database_cremona_ellcurve,database_jones_numfield,database_kohel,database_odlyzko_zeta,database_symbolic_data,dochtml,dot2tex,e_antic,fricas,gambit,gap_packages,giacpy_sage,latte_int,libsemigroups,lidia,lrslib,mcqd,meataxe,memlimit,normaliz,ore_algebra,p_group_cohomology,pari_jupyter,plantri,primecount,pynormaliz,python2,qhull,saclib,sage,tides,topcom
Doctesting 1 file.
sage -t ads.py
**********************************************************************
File "ads.py", line 70, in ads
Failed example:
    subsets(U)
Expected:
    <generator object powerset at 0x7fec5ffd33c0>
Got:
    <generator object powerset at 0x7f552730adc0>
**********************************************************************
File "ads.py", line 135, in ads
Failed example:
    def fa(x):
Exception raised:
    Traceback (most recent call last):
      File "/ext/sage/sage-8.9_1804/local/lib/python2.7/site-packages/sage/doctest/forker.py", line 681, in _run
        self.compile_and_execute(example, compiler, test.globs)
      File "/ext/sage/sage-8.9_1804/local/lib/python2.7/site-packages/sage/doctest/forker.py", line 1121, in compile_and_execute
        compiled = compiler(example)
      File "/ext/sage/sage-8.9_1804/local/lib/python2.7/site-packages/sage/doctest/forker.py", line 649, in compiler
        compileflags, 1)
      File "<doctest ads[23]>", line 1
        def fa(x):
                 ^
    SyntaxError: unexpected EOF while parsing
**********************************************************************
File "ads.py", line 136, in ads
Failed example:
      return x^2
Exception raised:
    Traceback (most recent call last):
      File "/ext/sage/sage-8.9_1804/local/lib/python2.7/site-packages/sage/doctest/forker.py", line 681, in _run
        self.compile_and_execute(example, compiler, test.globs)
      File "/ext/sage/sage-8.9_1804/local/lib/python2.7/site-packages/sage/doctest/forker.py", line 1121, in compile_and_execute
        compiled = compiler(example)
      File "/ext/sage/sage-8.9_1804/local/lib/python2.7/site-packages/sage/doctest/forker.py", line 649, in compiler
        compileflags, 1)
      File "<doctest ads[24]>", line 1
        return x**Integer(2)
        ^
    IndentationError: unexpected indent
**********************************************************************
File "ads.py", line 137, in ads
Failed example:
    [fa(2),fa(1.2)]
Exception raised:
    Traceback (most recent call last):
      File "/ext/sage/sage-8.9_1804/local/lib/python2.7/site-packages/sage/doctest/forker.py", line 681, in _run
        self.compile_and_execute(example, compiler, test.globs)
      File "/ext/sage/sage-8.9_1804/local/lib/python2.7/site-packages/sage/doctest/forker.py", line 1123, in compile_and_execute
        exec(compiled, globs)
      File "<doctest ads[25]>", line 1, in <module>
        [fa(Integer(2)),fa(RealNumber('1.2'))]
    NameError: name 'fa' is not defined
**********************************************************************
File "ads.py", line 170, in ads
Failed example:
    def D(n):
Exception raised:
    Traceback (most recent call last):
      File "/ext/sage/sage-8.9_1804/local/lib/python2.7/site-packages/sage/doctest/forker.py", line 681, in _run
        self.compile_and_execute(example, compiler, test.globs)
      File "/ext/sage/sage-8.9_1804/local/lib/python2.7/site-packages/sage/doctest/forker.py", line 1121, in compile_and_execute
        compiled = compiler(example)
      File "/ext/sage/sage-8.9_1804/local/lib/python2.7/site-packages/sage/doctest/forker.py", line 649, in compiler
        compileflags, 1)
      File "<doctest ads[29]>", line 1
        def D(n):
                ^
    SyntaxError: unexpected EOF while parsing
**********************************************************************
File "ads.py", line 171, in ads
Failed example:
      if n<=2:
Exception raised:
    Traceback (most recent call last):
      File "/ext/sage/sage-8.9_1804/local/lib/python2.7/site-packages/sage/doctest/forker.py", line 681, in _run
        self.compile_and_execute(example, compiler, test.globs)
      File "/ext/sage/sage-8.9_1804/local/lib/python2.7/site-packages/sage/doctest/forker.py", line 1121, in compile_and_execute
        compiled = compiler(example)
      File "/ext/sage/sage-8.9_1804/local/lib/python2.7/site-packages/sage/doctest/forker.py", line 649, in compiler
        compileflags, 1)
      File "<doctest ads[30]>", line 1
        if n<=Integer(2):
        ^
    IndentationError: unexpected indent
**********************************************************************
File "ads.py", line 172, in ads
Failed example:
              return n-1
Exception raised:
    Traceback (most recent call last):
      File "/ext/sage/sage-8.9_1804/local/lib/python2.7/site-packages/sage/doctest/forker.py", line 681, in _run
        self.compile_and_execute(example, compiler, test.globs)
      File "/ext/sage/sage-8.9_1804/local/lib/python2.7/site-packages/sage/doctest/forker.py", line 1121, in compile_and_execute
        compiled = compiler(example)
      File "/ext/sage/sage-8.9_1804/local/lib/python2.7/site-packages/sage/doctest/forker.py", line 649, in compiler
        compileflags, 1)
      File "<doctest ads[31]>", line 1
        return n-Integer(1)
        ^
    IndentationError: unexpected indent
**********************************************************************
File "ads.py", line 173, in ads
Failed example:
      else:
Exception raised:
    Traceback (most recent call last):
      File "/ext/sage/sage-8.9_1804/local/lib/python2.7/site-packages/sage/doctest/forker.py", line 681, in _run
        self.compile_and_execute(example, compiler, test.globs)
      File "/ext/sage/sage-8.9_1804/local/lib/python2.7/site-packages/sage/doctest/forker.py", line 1121, in compile_and_execute
        compiled = compiler(example)
      File "/ext/sage/sage-8.9_1804/local/lib/python2.7/site-packages/sage/doctest/forker.py", line 649, in compiler
        compileflags, 1)
      File "<doctest ads[32]>", line 1
        else:
        ^
    IndentationError: unexpected indent
**********************************************************************
File "ads.py", line 174, in ads
Failed example:
              return (n-1)*(D(n-2)+D(n-1))
Exception raised:
    Traceback (most recent call last):
      File "/ext/sage/sage-8.9_1804/local/lib/python2.7/site-packages/sage/doctest/forker.py", line 681, in _run
        self.compile_and_execute(example, compiler, test.globs)
      File "/ext/sage/sage-8.9_1804/local/lib/python2.7/site-packages/sage/doctest/forker.py", line 1121, in compile_and_execute
        compiled = compiler(example)
      File "/ext/sage/sage-8.9_1804/local/lib/python2.7/site-packages/sage/doctest/forker.py", line 649, in compiler
        compileflags, 1)
      File "<doctest ads[33]>", line 1
        return (n-Integer(1))*(D(n-Integer(2))+D(n-Integer(1)))
        ^
    IndentationError: unexpected indent
**********************************************************************
File "ads.py", line 176, in ads
Failed example:
    list(map(lambda k:[k,D(k),(D(k)/factorial(k)).n(digits=8)],range(1,16)))
Exception raised:
    Traceback (most recent call last):
      File "/ext/sage/sage-8.9_1804/local/lib/python2.7/site-packages/sage/doctest/forker.py", line 681, in _run
        self.compile_and_execute(example, compiler, test.globs)
      File "/ext/sage/sage-8.9_1804/local/lib/python2.7/site-packages/sage/doctest/forker.py", line 1123, in compile_and_execute
        exec(compiled, globs)
      File "<doctest ads[34]>", line 1, in <module>
        list(map(lambda k:[k,D(k),(D(k)/factorial(k)).n(digits=Integer(8))],range(Integer(1),Integer(16))))
      File "<doctest ads[34]>", line 1, in <lambda>
        list(map(lambda k:[k,D(k),(D(k)/factorial(k)).n(digits=Integer(8))],range(Integer(1),Integer(16))))
    NameError: global name 'D' is not defined
**********************************************************************
File "ads.py", line 195, in ads
Failed example:
    var('z')
Expected nothing
Got:
    z
**********************************************************************
File "ads.py", line 214, in ads
Failed example:
    M = Matrix([[0,1,0,0,0],[0,0,1,0,0],[0,0,0,1,0],
Exception raised:
    Traceback (most recent call last):
      File "/ext/sage/sage-8.9_1804/local/lib/python2.7/site-packages/sage/doctest/forker.py", line 681, in _run
        self.compile_and_execute(example, compiler, test.globs)
      File "/ext/sage/sage-8.9_1804/local/lib/python2.7/site-packages/sage/doctest/forker.py", line 1121, in compile_and_execute
        compiled = compiler(example)
      File "/ext/sage/sage-8.9_1804/local/lib/python2.7/site-packages/sage/doctest/forker.py", line 649, in compiler
        compileflags, 1)
      File "<doctest ads[40]>", line 1
        M = Matrix([[Integer(0),Integer(1),Integer(0),Integer(0),Integer(0)],[Integer(0),Integer(0),Integer(1),Integer(0),Integer(0)],[Integer(0),Integer(0),Integer(0),Integer(1),Integer(0)],
                                                                                                                                                                                              ^
    SyntaxError: unexpected EOF while parsing
**********************************************************************
File "ads.py", line 215, in ads
Failed example:
                      [0,0,0,0,1],[1,0,0,0,0]])
Exception raised:
    Traceback (most recent call last):
      File "/ext/sage/sage-8.9_1804/local/lib/python2.7/site-packages/sage/doctest/forker.py", line 681, in _run
        self.compile_and_execute(example, compiler, test.globs)
      File "/ext/sage/sage-8.9_1804/local/lib/python2.7/site-packages/sage/doctest/forker.py", line 1121, in compile_and_execute
        compiled = compiler(example)
      File "/ext/sage/sage-8.9_1804/local/lib/python2.7/site-packages/sage/doctest/forker.py", line 649, in compiler
        compileflags, 1)
      File "<doctest ads[41]>", line 1
        [Integer(0),Integer(0),Integer(0),Integer(0),Integer(1)],[Integer(1),Integer(0),Integer(0),Integer(0),Integer(0)]])
        ^
    IndentationError: unexpected indent
**********************************************************************
File "ads.py", line 216, in ads
Failed example:
    DiGraph(M).show()
Exception raised:
    Traceback (most recent call last):
      File "/ext/sage/sage-8.9_1804/local/lib/python2.7/site-packages/sage/doctest/forker.py", line 681, in _run
        self.compile_and_execute(example, compiler, test.globs)
      File "/ext/sage/sage-8.9_1804/local/lib/python2.7/site-packages/sage/doctest/forker.py", line 1123, in compile_and_execute
        exec(compiled, globs)
      File "<doctest ads[42]>", line 1, in <module>
        DiGraph(M).show()
    NameError: name 'M' is not defined
**********************************************************************
File "ads.py", line 224, in ads
Failed example:
    DiGraph(M).edges()
Exception raised:
    Traceback (most recent call last):
      File "/ext/sage/sage-8.9_1804/local/lib/python2.7/site-packages/sage/doctest/forker.py", line 681, in _run
        self.compile_and_execute(example, compiler, test.globs)
      File "/ext/sage/sage-8.9_1804/local/lib/python2.7/site-packages/sage/doctest/forker.py", line 1123, in compile_and_execute
        exec(compiled, globs)
      File "<doctest ads[43]>", line 1, in <module>
        DiGraph(M).edges()
    NameError: name 'M' is not defined
**********************************************************************
File "ads.py", line 269, in ads
Failed example:
    list(Gr.breadth_first_search(0,report_distance='True'))
Expected:
    [(0, 0),(7, 1),(14, 1),(15, 1),(16, 2),(2, 2),(3, 2),(13, 2),(17, 2),
     (4, 2),(5, 2),(10, 2),(6, 2),(11, 2),(8, 3),(1, 3),(9, 3),(12, 3)]
Got:
    [(0, 0),
     (7, 1),
     (14, 1),
     (15, 1),
     (16, 2),
     (2, 2),
     (3, 2),
     (13, 2),
     (17, 2),
     (4, 2),
     (5, 2),
     (10, 2),
     (6, 2),
     (11, 2),
     (8, 3),
     (1, 3),
     (9, 3),
     (12, 3)]
**********************************************************************
File "ads.py", line 284, in ads
Failed example:
    edges=[(1, 2, 4), (2, 8, 4), (3, 8, 4), (4, 7, 5), (6, 8, 5), (1, 3, 6), (1, 7, 6), (4, 5, 6), (5, 10, 9), (2, 10, 7), (4, 6, 7), (2, 4, 8), (1,
Exception raised:
    Traceback (most recent call last):
      File "/ext/sage/sage-8.9_1804/local/lib/python2.7/site-packages/sage/doctest/forker.py", line 681, in _run
        self.compile_and_execute(example, compiler, test.globs)
      File "/ext/sage/sage-8.9_1804/local/lib/python2.7/site-packages/sage/doctest/forker.py", line 1121, in compile_and_execute
        compiled = compiler(example)
      File "/ext/sage/sage-8.9_1804/local/lib/python2.7/site-packages/sage/doctest/forker.py", line 649, in compiler
        compileflags, 1)
      File "<doctest ads[59]>", line 1
        edges=[(Integer(1), Integer(2), Integer(4)), (Integer(2), Integer(8), Integer(4)), (Integer(3), Integer(8), Integer(4)), (Integer(4), Integer(7), Integer(5)), (Integer(6), Integer(8), Integer(5)), (Integer(1), Integer(3), Integer(6)), (Integer(1), Integer(7), Integer(6)), (Integer(4), Integer(5), Integer(6)), (Integer(5), Integer(10), Integer(9)), (Integer(2), Integer(10), Integer(7)), (Integer(4), Integer(6), Integer(7)), (Integer(2), Integer(4), Integer(8)), (Integer(1),
                                                                                                                                                                                                                                                                                                                                                                                                                                                                                                    ^
    SyntaxError: unexpected EOF while parsing
**********************************************************************
File "ads.py", line 285, in ads
Failed example:
    8, 9), (1, 9, 9), (5, 6, 9), (1, 10, 10), (2, 9, 10), (4, 9, 10), (5, 9, 10), (6, 9, 10)]
Exception raised:
    Traceback (most recent call last):
      File "/ext/sage/sage-8.9_1804/local/lib/python2.7/site-packages/sage/doctest/forker.py", line 681, in _run
        self.compile_and_execute(example, compiler, test.globs)
      File "/ext/sage/sage-8.9_1804/local/lib/python2.7/site-packages/sage/doctest/forker.py", line 1121, in compile_and_execute
        compiled = compiler(example)
      File "/ext/sage/sage-8.9_1804/local/lib/python2.7/site-packages/sage/doctest/forker.py", line 649, in compiler
        compileflags, 1)
      File "<doctest ads[60]>", line 1
        Integer(8), Integer(9)), (Integer(1), Integer(9), Integer(9)), (Integer(5), Integer(6), Integer(9)), (Integer(1), Integer(10), Integer(10)), (Integer(2), Integer(9), Integer(10)), (Integer(4), Integer(9), Integer(10)), (Integer(5), Integer(9), Integer(10)), (Integer(6), Integer(9), Integer(10))]
                              ^
    SyntaxError: invalid syntax
**********************************************************************
File "ads.py", line 286, in ads
Failed example:
    G=Graph(edges)
Exception raised:
    Traceback (most recent call last):
      File "/ext/sage/sage-8.9_1804/local/lib/python2.7/site-packages/sage/doctest/forker.py", line 681, in _run
        self.compile_and_execute(example, compiler, test.globs)
      File "/ext/sage/sage-8.9_1804/local/lib/python2.7/site-packages/sage/doctest/forker.py", line 1123, in compile_and_execute
        exec(compiled, globs)
      File "<doctest ads[61]>", line 1, in <module>
        G=Graph(edges)
    NameError: name 'edges' is not defined
**********************************************************************
File "ads.py", line 287, in ads
Failed example:
    G.weighted(True)
Exception raised:
    Traceback (most recent call last):
      File "/ext/sage/sage-8.9_1804/local/lib/python2.7/site-packages/sage/doctest/forker.py", line 681, in _run
        self.compile_and_execute(example, compiler, test.globs)
      File "/ext/sage/sage-8.9_1804/local/lib/python2.7/site-packages/sage/doctest/forker.py", line 1123, in compile_and_execute
        exec(compiled, globs)
      File "<doctest ads[62]>", line 1, in <module>
        G.weighted(True)
    NameError: name 'G' is not defined
**********************************************************************
File "ads.py", line 288, in ads
Failed example:
    G.graphplot(edge_labels=True,save_pos=True).show()
Exception raised:
    Traceback (most recent call last):
      File "/ext/sage/sage-8.9_1804/local/lib/python2.7/site-packages/sage/doctest/forker.py", line 681, in _run
        self.compile_and_execute(example, compiler, test.globs)
      File "/ext/sage/sage-8.9_1804/local/lib/python2.7/site-packages/sage/doctest/forker.py", line 1123, in compile_and_execute
        exec(compiled, globs)
      File "<doctest ads[63]>", line 1, in <module>
        G.graphplot(edge_labels=True,save_pos=True).show()
    NameError: name 'G' is not defined
**********************************************************************
File "ads.py", line 293, in ads
Failed example:
    E = kruskal(G, check=True);E
Exception raised:
    Traceback (most recent call last):
      File "/ext/sage/sage-8.9_1804/local/lib/python2.7/site-packages/sage/doctest/forker.py", line 681, in _run
        self.compile_and_execute(example, compiler, test.globs)
      File "/ext/sage/sage-8.9_1804/local/lib/python2.7/site-packages/sage/doctest/forker.py", line 1123, in compile_and_execute
        exec(compiled, globs)
      File "<doctest ads[65]>", line 1, in <module>
        E = kruskal(G, check=True);E
    NameError: name 'G' is not defined
**********************************************************************
File "ads.py", line 298, in ads
Failed example:
    T=Graph(E)
Exception raised:
    Traceback (most recent call last):
      File "/ext/sage/sage-8.9_1804/local/lib/python2.7/site-packages/sage/doctest/forker.py", line 681, in _run
        self.compile_and_execute(example, compiler, test.globs)
      File "/ext/sage/sage-8.9_1804/local/lib/python2.7/site-packages/sage/doctest/forker.py", line 1123, in compile_and_execute
        exec(compiled, globs)
      File "<doctest ads[66]>", line 1, in <module>
        T=Graph(E)
      File "/ext/sage/sage-8.9_1804/local/lib/python2.7/site-packages/sage/graphs/graph.py", line 1120, in __init__
        raise ValueError("This input cannot be turned into a graph")
    ValueError: This input cannot be turned into a graph
**********************************************************************
File "ads.py", line 299, in ads
Failed example:
    T.set_pos(G.get_pos())
Exception raised:
    Traceback (most recent call last):
      File "/ext/sage/sage-8.9_1804/local/lib/python2.7/site-packages/sage/doctest/forker.py", line 681, in _run
        self.compile_and_execute(example, compiler, test.globs)
      File "/ext/sage/sage-8.9_1804/local/lib/python2.7/site-packages/sage/doctest/forker.py", line 1123, in compile_and_execute
        exec(compiled, globs)
      File "<doctest ads[67]>", line 1, in <module>
        T.set_pos(G.get_pos())
    NameError: name 'T' is not defined
**********************************************************************
File "ads.py", line 300, in ads
Failed example:
    T.graphplot(edge_labels=True).show()
Exception raised:
    Traceback (most recent call last):
      File "/ext/sage/sage-8.9_1804/local/lib/python2.7/site-packages/sage/doctest/forker.py", line 681, in _run
        self.compile_and_execute(example, compiler, test.globs)
      File "/ext/sage/sage-8.9_1804/local/lib/python2.7/site-packages/sage/doctest/forker.py", line 1123, in compile_and_execute
        exec(compiled, globs)
      File "<doctest ads[68]>", line 1, in <module>
        T.graphplot(edge_labels=True).show()
    NameError: name 'T' is not defined
**********************************************************************
File "ads.py", line 326, in ads
Failed example:
    while b>0:
        print('computing gcd of '+str(a)+' and '+str(b))
        [a,b]=[b,a%b]
Expected nothing
Got:
    computing gcd of 99 and 53
    computing gcd of 53 and 46
    computing gcd of 46 and 7
    computing gcd of 7 and 4
    computing gcd of 4 and 3
    computing gcd of 3 and 1
**********************************************************************
File "ads.py", line 329, in ads
Failed example:
    print('result is '+str(a))
Expected:
    computing gcd of 99 and 53
    computing gcd of 53 and 46
    computing gcd of 46 and 7
    computing gcd of 7 and 4
    computing gcd of 4 and 3
    computing gcd of 3 and 1
    result is 1
Got:
    result is 1
**********************************************************************
File "ads.py", line 350, in ads
Failed example:
    print(gcd(a,b))
Expected nothing
Got:
    1
**********************************************************************
File "ads.py", line 351, in ads
Failed example:
    print(xgcd(a,b))
Expected:
    1
    (1, -173, 622)
Got:
    (1, -173, 622)
**********************************************************************
File "ads.py", line 358, in ads
Failed example:
    print(R.addition_table('elements'))
Expected nothing
Got:
    +  0 1 2 3 4 5
     +------------
    0| 0 1 2 3 4 5
    1| 1 2 3 4 5 0
    2| 2 3 4 5 0 1
    3| 3 4 5 0 1 2
    4| 4 5 0 1 2 3
    5| 5 0 1 2 3 4
    <BLANKLINE>
**********************************************************************
File "ads.py", line 359, in ads
Failed example:
    print(R.multiplication_table('elements'))
Expected:
    +  0 1 2 3 4 5
     +------------  
    0| 0 1 2 3 4 5
    1| 1 2 3 4 5 0
    2| 2 3 4 5 0 1
    3| 3 4 5 0 1 2
    4| 4 5 0 1 2 3
    5| 5 0 1 2 3 4
Got:
    *  0 1 2 3 4 5
     +------------
    0| 0 0 0 0 0 0
    1| 0 1 2 3 4 5
    2| 0 2 4 0 2 4
    3| 0 3 0 3 0 3
    4| 0 4 2 0 4 2
    5| 0 5 4 3 2 1
    <BLANKLINE>
**********************************************************************
File "ads.py", line 399, in ads
Failed example:
    C.echelon_form()
Expected:
    [1  0       0       1/2     1/2]
    [0  1       0       -3/2    3/2]
    [0  0       1         0     -1]
Got:
    [   1    0    0  1/2  1/2]
    [   0    1    0 -3/2  3/2]
    [   0    0    1    0   -1]
**********************************************************************
File "ads.py", line 415, in ads
Failed example:
    C3.echelon_form()
Expected:
    [    1.000000    0.0000000    0.0000000    0.5000000    0.500000000000000]
    [   0.0000000     1.000000    0.0000000    -1.500000     1.50000000000000]
    [   0.0000000    0.0000000     1.000000   4.934324e-17  -1.00000000000000]
Got:
    [    1.00000000000000    0.000000000000000    0.000000000000000    0.500000000000000    0.500000000000000]
    [   0.000000000000000     1.00000000000000    0.000000000000000    -1.50000000000000     1.50000000000000]
    [   0.000000000000000    0.000000000000000     1.00000000000000 4.93432455388958e-17    -1.00000000000000]
**********************************************************************
File "ads.py", line 422, in ads
Failed example:
    var (' D, P')
Expected nothing
Got:
    (D, P)
**********************************************************************
File "ads.py", line 430, in ads
Failed example:
    (D,P)=A.right_eigenmatrix();(D,P)
Expected:
    ([6 0 0]
    [0 4 0]
    [0 0 3], 
    [ 1  1  1]
    [ 2  0 -1]
    [ 1 -1  1])
Got:
    (
    [6 0 0]  [ 1  1  1]
    [0 4 0]  [ 2  0 -1]
    [0 0 3], [ 1 -1  1]
    )
**********************************************************************
File "ads.py", line 455, in ads
Failed example:
    P.numerical_approx(digits=3)
Expected nothing
Got:
    [  1.00   1.00   1.00]
    [ -3.65 -0.726  0.377]
    [  1.38  -2.65  0.274]
**********************************************************************
File "ads.py", line 456, in ads
Failed example:
    print('------------------')
Expected nothing
Got:
    ------------------
**********************************************************************
File "ads.py", line 457, in ads
Failed example:
    D=(P.inverse()*A2*P);D.numerical_approx(digits=3)
Expected:
    [ 4.35 0.000 0.000]
    [0.000  7.27 0.000]
    [0.000 0.000  8.38]
Got:
    [     4.35  1.90e-19  5.76e-20]
    [-4.34e-19      7.27 -4.07e-19]
    [ 1.08e-19  4.34e-19      8.38]
**********************************************************************
File "ads.py", line 465, in ads
Failed example:
    (D,P)=A3.right_eigenmatrix();(D,P)
Expected:
    ([1 0 0]
    [0 3 0]
    [0 0 3], 
    [   1    0    0]
    [ 1/4    1    0]
    [-1/4    1    0])
Got:
    (
    [1 0 0]  [   1    0    0]
    [0 3 0]  [ 1/4    1    0]
    [0 0 3], [-1/4    1    0]
    )
**********************************************************************
File "ads.py", line 562, in ads
Failed example:
    slow_exp(2,5,7)
Expected nothing
Got:
    4
**********************************************************************
File "ads.py", line 575, in ads
Failed example:
    fast_exp(2,5,7)
Expected nothing
Got:
    4
**********************************************************************
File "ads.py", line 587, in ads
Failed example:
    gcd(1001,154)  #test
Expected nothing
Got:
    77
**********************************************************************
File "ads.py", line 625, in ads
Failed example:
    print('done')
Expected:
    'done'
Got:
    done
**********************************************************************
File "ads.py", line 637, in ads
Failed example:
    else:
        fruit_color['Red']=['raspberry']
Exception raised:
    Traceback (most recent call last):
      File "/ext/sage/sage-8.9_1804/local/lib/python2.7/site-packages/sage/doctest/forker.py", line 681, in _run
        self.compile_and_execute(example, compiler, test.globs)
      File "/ext/sage/sage-8.9_1804/local/lib/python2.7/site-packages/sage/doctest/forker.py", line 1121, in compile_and_execute
        compiled = compiler(example)
      File "/ext/sage/sage-8.9_1804/local/lib/python2.7/site-packages/sage/doctest/forker.py", line 649, in compiler
        compileflags, 1)
      File "<doctest ads[156]>", line 1
        else:
           ^
    SyntaxError: invalid syntax
**********************************************************************
File "ads.py", line 639, in ads
Failed example:
    fruit_color['Red']
Expected:
    ['apple', 'pomegranate', 'blood orange', 'raspberry', 'raspberry']
Got:
    ['apple', 'pomegranate', 'blood orange', 'raspberry']
**********************************************************************
File "ads.py", line 644, in ads
Failed example:
    for fruit in fruit_color:
        print([fruit,fruit_color[fruit]])
Expected:
    ['Purple', ['plum', 'grape']]
    ['Orange', ['orange', 'pineapple']]
    ['Green', ['apple', 'pear', 'grape', 'lime']]
    ['Yellow', ['banana', 'apple', 'lemon']]
    ['Red', ['apple', 'pomegranate', 'blood orange','raspberry']]
Got:
    ['Purple', ['plum', 'grape']]
    ['Orange', ['orange', 'pineapple']]
    ['Green', ['apple', 'pear', 'grape', 'lime']]
    ['Yellow', ['banana', 'apple', 'lemon']]
    ['Red', ['apple', 'pomegranate', 'blood orange', 'raspberry']]
**********************************************************************
File "ads.py", line 654, in ads
Failed example:
    DiGraph(fruit_color).plot()
Expected nothing
Got:
    Graphics object consisting of 33 graphics primitives
**********************************************************************
File "ads.py", line 664, in ads
Failed example:
    vertex_pos
Expected:
    {'Purple': (-5, 0), 'Orange': (-5, 1), 'Green': (-5, 2), 'Red': (-5, 4), 'Yellow': (-5, 3)}
Got:
    {'Green': (-5, 2),
     'Orange': (-5, 1),
     'Purple': (-5, 0),
     'Red': (-5, 4),
     'Yellow': (-5, 3)}
**********************************************************************
File "ads.py", line 676, in ads
Failed example:
    vertex_pos
Expected:
    {'blood orange': (5, 0), 'grape': (5, 1), 'apple': (5, 2), 'Purple': (-5, 0), 'plum': (5, 10), 'pomegranate': (5, 3), 'pear': (5, 4), 'Yellow': (-5, 3), 'orange': (5, 7), 'Green': (-5, 2), 'pineapple': (5, 6), 'Orange': (-5, 1), 'lemon': (5, 8), 'raspberry': (5, 9), 'banana': (5, 5), 'Red': (-5, 4), 'lime': (5, 11)}
Got:
    {'Green': (-5, 2),
     'Orange': (-5, 1),
     'Purple': (-5, 0),
     'Red': (-5, 4),
     'Yellow': (-5, 3),
     'apple': (5, 2),
     'banana': (5, 5),
     'blood orange': (5, 0),
     'grape': (5, 1),
     'lemon': (5, 8),
     'lime': (5, 11),
     'orange': (5, 7),
     'pear': (5, 4),
     'pineapple': (5, 6),
     'plum': (5, 10),
     'pomegranate': (5, 3),
     'raspberry': (5, 9)}
**********************************************************************
File "ads.py", line 681, in ads
Failed example:
    DiGraph(fruit_color).plot(pos=vertex_pos,vertex_size=1)
Expected nothing
Got:
    Graphics object consisting of 33 graphics primitives
**********************************************************************
1 item had failures:
  50 of 176 in ads
    Error: TAB character found at lines 136,171,172,.,.,.,402
    [175 tests, 50 failures, 5.30 s]
----------------------------------------------------------------------
sage -t ads.py  # Tab character found
sage -t ads.py  # 50 doctests failed
----------------------------------------------------------------------
Total time for all tests: 5.4 seconds
    cpu time: 4.6 seconds
    cumulative wall time: 5.3 seconds
